Workbook

Sheet 📋 Instrucciones
B2: PLANTILLA DE ANÁLISIS DE ENCUESTAS — TRABAJO DE GRADO
B3: Aplicación móvil multimodal para gestión de medicamentos domiciliarios
B5: ℹ️ CONTENIDO DEL LIBRO
B6: Hoja 1 | C6: 📋 Instrucciones — Este documento
B7: Hojas 2–5 | C7: Datos Perfil 1, 2, 3 y 4 — Ingreso de respuestas Likert y datos del participante
B8: Hoja 6 | C8: 📊 Análisis — Estadísticas descriptivas automáticas por perfil e ítem
B9: Hoja 7 | C9: 🔀 Comparación — Comparación de medias entre los 4 perfiles
B10: Hoja 8 | C10: 📝 Preguntas Abiertas — Registro y codificación de respuestas cualitativas
B11: Hoja 9 | C11: 🏆 Requisitos — Ranking automático de requisitos por prioridad
B13: ✏️ CÓMO INGRESAR DATOS
B14: Paso 1 | C14: Ir a la hoja del perfil correspondiente (ej. 'P1 Adulto Mayor')
B15: Paso 2 | C15: Ingresar los datos del participante en las columnas B–G
B16: Paso 3 | C16: Ingresar las respuestas Likert (solo valores 1 a 5) en las columnas H–AA
B17: Paso 4 | C17: Las celdas en AMARILLO tienen validación — solo aceptan 1, 2, 3, 4 o 5
B18: Paso 5 | C18: Los análisis en las hojas 6–9 se actualizan automáticamente
B20: 🎨 CÓDIGO DE COLORES DE LOS PERFILES
B21: Perfil 1 | C21: 65+ años | Múltiples medicamentos crónicos | Alta necesidad de accesibilidad
B22: Perfil 2 | C22: 40–64 años | Pocos medicamentos crónicos | Recordatorios discretos + inventario básico
B23: Perfil 3 | C23: 18–39 años | Tratamientos cortos/intermitentes | Interfaz moderna + reposición rápida
B24: Perfil 4 | C24: Edad variable | Cuidadores medicos
B26: ⚠️ REGLAS IMPORTANTES
B27: Validación | C27: Solo ingresar valores 1–5 en celdas de respuesta Likert. No dejar celdas en 0.
B28: Participantes | C28: Cada fila = 1 participante. No combinar perfiles en la misma hoja.
B29: Fórmulas | C29: NO modificar las columnas AB en adelante (son cálculos automáticos).
B30: Preguntas abiertas | C30: Registrar en la hoja 'Preguntas Abiertas' con su código y perfil.
B31: Respaldo | C31: Guardar una copia del archivo antes de ingresar datos masivos.

Sheet P1 1
B2: Perfil 1 — Plantilla de Ingreso de Datos
H3: Accesibilidad Multimodal | M3: Interfaz Adultos Mayores | R3: Planificación y Recordatorios | W3: Inventario / Stock
B4: Código | C4: Fecha | D4: Edad | E4: Género | F4: Nombre | G4: Observaciones | H4: Ítem 1 | I4: Ítem 2 | J4: Ítem 3 | K4: Ítem 4 | L4: Ítem 5 | M4: Ítem 6 | N4: Ítem 7 | O4: Ítem 8 | P4: Ítem 9 | Q4: Ítem 10 | R4: Ítem 11 | S4: Ítem 12 | T4: Ítem 13 | U4: Ítem 14 | V4: Ítem 15 | W4: Ítem 16 | X4: Ítem 17 | Y4: Ítem 18 | Z4: Ítem 19 | AA4: Ítem 20 | AB4: Promedio | AC4: Desv. Estd. | AD4: Respuestas
H5: Prefiero hablarle a la app en lugar de escribir con el teclado. | I5: Me sería útil que la app me lea los recordatorios en voz alta. | J5: Usaría comandos de voz para confirmar la toma de un medicamento. | K5: Prefiero botones grandes y texto grande en la pantalla. | L5: Me costaría aprender a usar una aplicación nueva en el celular. | M5: Las letras pequeñas me dificultan el uso de apps en el celular. | N5: Prefiero pantallas con pocos elementos y sin mucha información. | O5: El buen contraste texto/fondo me ayuda a leer mejor. | P5: Me gustaría que los botones tengan etiqueta de texto debajo del ícono. | Q5: Necesito que alguien me ayude a configurar la app inicialmente. | R5: Se me olvida con frecuencia tomar alguno de mis medicamentos. | S5: Tengo dificultades para recordar cuándo tomar cada medicamento. | T5: Me sería útil un aviso de voz y sonido en el momento de tomar el med. | U5: Necesito un informe de mis tomas para mostrar al médico o cuidador. | V5: Me ayudaría ver el horario de todos mis medicamentos del día en una pantalla. | W5: Se me ha acabado algún medicamento en casa sin darme cuenta a tiempo. | X5: Me sería útil que la app avise cuando queda poco medicamento. | Y5: Necesito recordatorios para ir a la farmacia o reclamar medicamentos. | Z5: Me gustaría que la app lleve automáticamente el conteo de pastillas. | AA5: Me sería difícil llevar un control manual de medicamentos en casa. | AB5: Auto-calculado | AC5: Auto-calculado | AD5: Auto-calculado
B6: P1-01 | C6: 46003 | D6: 68 | E6: F | F6: Esperanza Gonzales Yepes | G6: Problemas cardiovasculares, presion alta | H6: 5 | I6: 5 | J6: 1 | K6: 3 | L6: 5 | M6: 3 | N6: 4 | O6: 5 | P6: 5 | Q6: 5 | R6: 1 | S6: 1 | T6: 5 | U6: 5 | V6: 3 | W6: 1 | X6: 1 | Y6: 1 | Z6: 1 | AA6: 1 | AB6: =IFERROR(AVERAGEIF(H6:AA6,">=1"),"—") -> 3.05 | AC6: =IFERROR(STDEV(H6:AA6),"—") -> 1.8488973 | AD6: =COUNTIF(H6:AA6,">=1") -> 20
B7: P1-02 | C7: 46047 | D7: 62 | E7: F | F7: Maria Floralba Barajas Jaimes | G7: Parkinson | H7: 2 | I7: 5 | J7: 4 | K7: 4 | L7: 5 | M7: 4 | N7: 4 | O7: 4 | P7: 4 | Q7: 5 | R7: 1 | S7: 1 | T7: 4 | U7: 1 | V7: 4 | W7: 1 | X7: 5 | Y7: 5 | Z7: 4 | AA7: 1 | AB7: =IFERROR(AVERAGEIF(H7:AA7,">=1"),"—") -> 3.4 | AC7: =IFERROR(STDEV(H7:AA7),"—") -> 1.5694451 | AD7: =COUNTIF(H7:AA7,">=1") -> 20
B8: P1-03 | C8: 46293 | D8: 74 | E8: F | F8: Flor De Maria Crispin Blanco | G8: Bronquitis Cronica | H8: 5 | I8: 5 | J8: 5 | K8: 5 | L8: 5 | M8: 5 | N8: 5 | O8: 4 | P8: 3 | Q8: 5 | R8: 3 | S8: 3 | T8: 5 | U8: 2 | V8: 1 | W8: 3 | X8: 5 | Y8: 3 | Z8: 5 | AA8: 3 | AB8: =IFERROR(AVERAGEIF(H8:AA8,">=1"),"—") -> 4 | AC8: =IFERROR(STDEV(H8:AA8),"—") -> 1.2565617 | AD8: =COUNTIF(H8:AA8,">=1") -> 20
B9: P1-04 | AB9: =IFERROR(AVERAGEIF(H9:AA9,">=1"),"—") -> — | AC9: =IFERROR(STDEV(H9:AA9),"—") -> — | AD9: =COUNTIF(H9:AA9,">=1") -> 0
B10: P1-05 | AB10: =IFERROR(AVERAGEIF(H10:AA10,">=1"),"—") -> — | AC10: =IFERROR(STDEV(H10:AA10),"—") -> — | AD10: =COUNTIF(H10:AA10,">=1") -> 0
B11: P1-06 | AB11: =IFERROR(AVERAGEIF(H11:AA11,">=1"),"—") -> — | AC11: =IFERROR(STDEV(H11:AA11),"—") -> — | AD11: =COUNTIF(H11:AA11,">=1") -> 0
B12: P1-07 | AB12: =IFERROR(AVERAGEIF(H12:AA12,">=1"),"—") -> — | AC12: =IFERROR(STDEV(H12:AA12),"—") -> — | AD12: =COUNTIF(H12:AA12,">=1") -> 0
B13: P1-08 | AB13: =IFERROR(AVERAGEIF(H13:AA13,">=1"),"—") -> — | AC13: =IFERROR(STDEV(H13:AA13),"—") -> — | AD13: =COUNTIF(H13:AA13,">=1") -> 0
B14: P1-09 | AB14: =IFERROR(AVERAGEIF(H14:AA14,">=1"),"—") -> — | AC14: =IFERROR(STDEV(H14:AA14),"—") -> — | AD14: =COUNTIF(H14:AA14,">=1") -> 0
B15: P1-10 | AB15: =IFERROR(AVERAGEIF(H15:AA15,">=1"),"—") -> — | AC15: =IFERROR(STDEV(H15:AA15),"—") -> — | AD15: =COUNTIF(H15:AA15,">=1") -> 0
B16: P1-11 | AB16: =IFERROR(AVERAGEIF(H16:AA16,">=1"),"—") -> — | AC16: =IFERROR(STDEV(H16:AA16),"—") -> — | AD16: =COUNTIF(H16:AA16,">=1") -> 0
B17: P1-12 | AB17: =IFERROR(AVERAGEIF(H17:AA17,">=1"),"—") -> — | AC17: =IFERROR(STDEV(H17:AA17),"—") -> — | AD17: =COUNTIF(H17:AA17,">=1") -> 0
B18: P1-13 | AB18: =IFERROR(AVERAGEIF(H18:AA18,">=1"),"—") -> — | AC18: =IFERROR(STDEV(H18:AA18),"—") -> — | AD18: =COUNTIF(H18:AA18,">=1") -> 0
B19: P1-14 | AB19: =IFERROR(AVERAGEIF(H19:AA19,">=1"),"—") -> — | AC19: =IFERROR(STDEV(H19:AA19),"—") -> — | AD19: =COUNTIF(H19:AA19,">=1") -> 0
B20: P1-15 | AB20: =IFERROR(AVERAGEIF(H20:AA20,">=1"),"—") -> — | AC20: =IFERROR(STDEV(H20:AA20),"—") -> — | AD20: =COUNTIF(H20:AA20,">=1") -> 0
... B25: P1-20 | AB25: =IFERROR(AVERAGEIF(H25:AA25,">=1"),"—") -> — | AC25: =IFERROR(STDEV(H25:AA25),"—") -> — | AD25: =COUNTIF(H25:AA25,">=1") -> 0
B28: Media por ítem | H28: =IFERROR(AVERAGEIF(H6:H25,">=1"), "—") -> 4 | I28: =IFERROR(AVERAGEIF(I6:I25,">=1"), "—") -> 5 | J28: =IFERROR(AVERAGEIF(J6:J25,">=1"), "—") -> 3.3333333 | K28: =IFERROR(AVERAGEIF(K6:K25,">=1"), "—") -> 4 | L28: =IFERROR(AVERAGEIF(L6:L25,">=1"), "—") -> 5 | M28: =IFERROR(AVERAGEIF(M6:M25,">=1"), "—") -> 4 | N28: =IFERROR(AVERAGEIF(N6:N25,">=1"), "—") -> 4.3333333 | O28: =IFERROR(AVERAGEIF(O6:O25,">=1"), "—") -> 4.3333333 | ... AA28: =IFERROR(AVERAGEIF(AA6:AA25,">=1"), "—") -> 1.6666667 | AB28: =IFERROR(AVERAGE(H28:AA28),"—") -> 3.4833333
B29: Desv. Estándar | H29: =IFERROR(STDEV(H6:H25),"—") -> 1.7320508 | I29: =IFERROR(STDEV(I6:I25),"—") -> 0 | J29: =IFERROR(STDEV(J6:J25),"—") -> 2.081666 | K29: =IFERROR(STDEV(K6:K25),"—") -> 1 | L29: =IFERROR(STDEV(L6:L25),"—") -> 0 | M29: =IFERROR(STDEV(M6:M25),"—") -> 1 | N29: =IFERROR(STDEV(N6:N25),"—") -> 0.57735027 | O29: =IFERROR(STDEV(O6:O25),"—") -> 0.57735027 | ... AA29: =IFERROR(STDEV(AA6:AA25),"—") -> 1.1547005 | AB29: =IFERROR(AVERAGE(H29:AA29),"—") -> 1.1582414
B30: Mínimo | H30: =IFERROR(_xlfn.MINIFS(H6:H25,H6:H25,">=1"),"—") -> 2 | I30: =IFERROR(_xlfn.MINIFS(I6:I25,I6:I25,">=1"),"—") -> 5 | J30: =IFERROR(_xlfn.MINIFS(J6:J25,J6:J25,">=1"),"—") -> 1 | K30: =IFERROR(_xlfn.MINIFS(K6:K25,K6:K25,">=1"),"—") -> 3 | L30: =IFERROR(_xlfn.MINIFS(L6:L25,L6:L25,">=1"),"—") -> 5 | M30: =IFERROR(_xlfn.MINIFS(M6:M25,M6:M25,">=1"),"—") -> 3 | N30: =IFERROR(_xlfn.MINIFS(N6:N25,N6:N25,">=1"),"—") -> 4 | O30: =IFERROR(_xlfn.MINIFS(O6:O25,O6:O25,">=1"),"—") -> 4 | ... AA30: =IFERROR(_xlfn.MINIFS(AA6:AA25,AA6:AA25,">=1"),"—") -> 1 | AB30: =IFERROR(AVERAGE(H30:AA30),"—") -> 2.4
B31: Máximo | H31: =IFERROR(MAX(H6:H25),"—") -> 5 | I31: =IFERROR(MAX(I6:I25),"—") -> 5 | J31: =IFERROR(MAX(J6:J25),"—") -> 5 | K31: =IFERROR(MAX(K6:K25),"—") -> 5 | L31: =IFERROR(MAX(L6:L25),"—") -> 5 | M31: =IFERROR(MAX(M6:M25),"—") -> 5 | N31: =IFERROR(MAX(N6:N25),"—") -> 5 | O31: =IFERROR(MAX(O6:O25),"—") -> 5 | ... AA31: =IFERROR(MAX(AA6:AA25),"—") -> 3 | AB31: =IFERROR(AVERAGE(H31:AA31),"—") -> 4.55
B32: % Acuerdo (≥4) | H32: =IFERROR(COUNTIF(H6:H25,">=4")/COUNTIF(H6:H25,">=1"),"—") -> 0.66666667 | I32: =IFERROR(COUNTIF(I6:I25,">=4")/COUNTIF(I6:I25,">=1"),"—") -> 1 | J32: =IFERROR(COUNTIF(J6:J25,">=4")/COUNTIF(J6:J25,">=1"),"—") -> 0.66666667 | K32: =IFERROR(COUNTIF(K6:K25,">=4")/COUNTIF(K6:K25,">=1"),"—") -> 0.66666667 | L32: =IFERROR(COUNTIF(L6:L25,">=4")/COUNTIF(L6:L25,">=1"),"—") -> 1 | M32: =IFERROR(COUNTIF(M6:M25,">=4")/COUNTIF(M6:M25,">=1"),"—") -> 0.66666667 | N32: =IFERROR(COUNTIF(N6:N25,">=4")/COUNTIF(N6:N25,">=1"),"—") -> 1 | O32: =IFERROR(COUNTIF(O6:O25,">=4")/COUNTIF(O6:O25,">=1"),"—") -> 1 | ... AA32: =IFERROR(COUNTIF(AA6:AA25,">=4")/COUNTIF(AA6:AA25,">=1"),"—") -> 0 | AB32: =IFERROR(AVERAGE(H32:AA32),"—") -> 0.58333333

Sheet P2 2
B2: Perfil 2 — Plantilla de Ingreso de Datos
H3: Usabilidad y Accesibilidad | M3: Planificación y Recordatorios | R3: Inventario y Alertas | W3: Interfaz e Integración
B4: Código | C4: Fecha | D4: Edad | E4: Género | F4: Nombres | G4: Observaciones | H4: Ítem 1 | I4: Ítem 2 | J4: Ítem 3 | K4: Ítem 4 | L4: Ítem 5 | M4: Ítem 6 | N4: Ítem 7 | O4: Ítem 8 | P4: Ítem 9 | Q4: Ítem 10 | R4: Ítem 11 | S4: Ítem 12 | T4: Ítem 13 | U4: Ítem 14 | V4: Ítem 15 | W4: Ítem 16 | X4: Ítem 17 | Y4: Ítem 18 | Z4: Ítem 19 | AA4: Ítem 20 | AB4: Promedio | AC4: Desv. Estd. | AD4: Respuestas
H5: Prefiero usar comandos de voz antes que texto en apps móviles. | I5: Me sería útil que la app me lea los recordatorios en voz alta. | J5: Usaría comandos de voz para confirmar la toma de un medicamento. | K5: Prefiero interfaces simples y con pocos objetos en pantalla | L5: Me cuesta aprender a usar aplicaciones nuevas en el celular. | M5: Las letras pequeñas me dificultan el uso de apps en el celular. | N5: Prefiero pantallas con pocos elementos y sin mucha información. | O5: El buen contraste texto/fondo me ayuda a leer mejor. | P5: Me gustaría que los botones tengan etiqueta de texto debajo del ícono. | Q5: Necesito que alguien me ayude a configurar la app inicialmente. | R5: Se me olvida con frecuencia tomar alguno de mis medicamentos. | S5: Tengo dificultades para recordar cuándo tomar cada medicamento. | T5: Me sería útil un aviso de voz y sonido en el momento de tomar el med. | U5: Necesito un informe de mis tomas para mostrar al médico o cuidador. | V5: Me ayudaría ver el horario de todos mis medicamentos del día en una pantalla. | W5: Se me ha acabado algún medicamento en casa sin darme cuenta a tiempo. | X5: Me sería útil que la app avise cuando queda poco medicamento. | Y5: Necesito recordatorios para ir a la farmacia o reclamar medicamentos. | Z5: Me gustaría que la app lleve automáticamente el conteo de pastillas. | AA5: Me sería difícil llevar un control manual de medicamentos en casa. | AB5: Auto-calculado | AC5: Auto-calculado | AD5: Auto-calculado
B6: P2-01 | C6: 46003 | D6: 56 | E6: F | F6: Miriam Jaimes Quintero | G6: Diabetes, colesterol y trigliceridos elevados | H6: 4 | I6: 5 | J6: 4 | K6: 4 | L6: 2 | M6: 5 | N6: 5 | O6: 3 | P6: 3 | Q6: 4 | R6: 1 | S6: 1 | T6: 4 | U6: 2 | V6: 4 | W6: 1 | X6: 5 | Y6: 5 | Z6: 4 | AA6: 1 | AB6: =IFERROR(AVERAGEIF(H6:AA6,">=1"),"—") -> 3.35 | AC6: =IFERROR(STDEV(H6:AA6),"—") -> 1.4964871 | AD6: =COUNTIF(H6:AA6,">=1") -> 20
B7: P2-02 | C7: 45966 | D7: 49 | E7: F | F7: Diana Patricia Gonzales | G7: Glaucoma, presion arteria, colesterol y triglic altos | H7: 2 | I7: 4 | J7: 5 | K7: 4 | L7: 2 | M7: 5 | N7: 5 | O7: 3 | P7: 3 | Q7: 4 | R7: 4 | S7: 4 | T7: 5 | U7: 3 | V7: 4 | W7: 4 | X7: 5 | Y7: 5 | Z7: 4 | AA7: 3 | AB7: =IFERROR(AVERAGEIF(H7:AA7,">=1"),"—") -> 3.9 | AC7: =IFERROR(STDEV(H7:AA7),"—") -> 0.96790604 | AD7: =COUNTIF(H7:AA7,">=1") -> 20
B8: P2-03 | C8: 45967 | D8: 57 | E8: M | F8: Luis Jesus Gomez Escobar | G8: Infarto, Problemas cardiacos | H8: 3 | I8: 5 | J8: 5 | K8: 3 | L8: 4 | M8: 5 | N8: 5 | O8: 5 | P8: 3 | Q8: 5 | R8: 5 | S8: 5 | T8: 5 | U8: 2 | V8: 5 | W8: 5 | X8: 5 | Y8: 5 | Z8: 5 | AA8: 5 | AB8: =IFERROR(AVERAGEIF(H8:AA8,">=1"),"—") -> 4.5 | AC8: =IFERROR(STDEV(H8:AA8),"—") -> 0.9459053 | AD8: =COUNTIF(H8:AA8,">=1") -> 20
B9: P2-04 | AB9: =IFERROR(AVERAGEIF(H9:AA9,">=1"),"—") -> — | AC9: =IFERROR(STDEV(H9:AA9),"—") -> — | AD9: =COUNTIF(H9:AA9,">=1") -> 0
B10: P2-05 | AB10: =IFERROR(AVERAGEIF(H10:AA10,">=1"),"—") -> — | AC10: =IFERROR(STDEV(H10:AA10),"—") -> — | AD10: =COUNTIF(H10:AA10,">=1") -> 0
B11: P2-06 | AB11: =IFERROR(AVERAGEIF(H11:AA11,">=1"),"—") -> — | AC11: =IFERROR(STDEV(H11:AA11),"—") -> — | AD11: =COUNTIF(H11:AA11,">=1") -> 0
B12: P2-07 | AB12: =IFERROR(AVERAGEIF(H12:AA12,">=1"),"—") -> — | AC12: =IFERROR(STDEV(H12:AA12),"—") -> — | AD12: =COUNTIF(H12:AA12,">=1") -> 0
B13: P2-08 | AB13: =IFERROR(AVERAGEIF(H13:AA13,">=1"),"—") -> — | AC13: =IFERROR(STDEV(H13:AA13),"—") -> — | AD13: =COUNTIF(H13:AA13,">=1") -> 0
B14: P2-09 | AB14: =IFERROR(AVERAGEIF(H14:AA14,">=1"),"—") -> — | AC14: =IFERROR(STDEV(H14:AA14),"—") -> — | AD14: =COUNTIF(H14:AA14,">=1") -> 0
B15: P2-10 | AB15: =IFERROR(AVERAGEIF(H15:AA15,">=1"),"—") -> — | AC15: =IFERROR(STDEV(H15:AA15),"—") -> — | AD15: =COUNTIF(H15:AA15,">=1") -> 0
B16: P2-11 | AB16: =IFERROR(AVERAGEIF(H16:AA16,">=1"),"—") -> — | AC16: =IFERROR(STDEV(H16:AA16),"—") -> — | AD16: =COUNTIF(H16:AA16,">=1") -> 0
B17: P2-12 | AB17: =IFERROR(AVERAGEIF(H17:AA17,">=1"),"—") -> — | AC17: =IFERROR(STDEV(H17:AA17),"—") -> — | AD17: =COUNTIF(H17:AA17,">=1") -> 0
B18: P2-13 | AB18: =IFERROR(AVERAGEIF(H18:AA18,">=1"),"—") -> — | AC18: =IFERROR(STDEV(H18:AA18),"—") -> — | AD18: =COUNTIF(H18:AA18,">=1") -> 0
B19: P2-14 | AB19: =IFERROR(AVERAGEIF(H19:AA19,">=1"),"—") -> — | AC19: =IFERROR(STDEV(H19:AA19),"—") -> — | AD19: =COUNTIF(H19:AA19,">=1") -> 0
B20: P2-15 | AB20: =IFERROR(AVERAGEIF(H20:AA20,">=1"),"—") -> — | AC20: =IFERROR(STDEV(H20:AA20),"—") -> — | AD20: =COUNTIF(H20:AA20,">=1") -> 0
... B25: P2-20 | AB25: =IFERROR(AVERAGEIF(H25:AA25,">=1"),"—") -> — | AC25: =IFERROR(STDEV(H25:AA25),"—") -> — | AD25: =COUNTIF(H25:AA25,">=1") -> 0
B28: Media por ítem | H28: =IFERROR(AVERAGEIF(H6:H25,">=1"), "—") -> 3 | I28: =IFERROR(AVERAGEIF(I6:I25,">=1"), "—") -> 4.6666667 | J28: =IFERROR(AVERAGEIF(J6:J25,">=1"), "—") -> 4.6666667 | K28: =IFERROR(AVERAGEIF(K6:K25,">=1"), "—") -> 3.6666667 | L28: =IFERROR(AVERAGEIF(L6:L25,">=1"), "—") -> 2.6666667 | M28: =IFERROR(AVERAGEIF(M6:M25,">=1"), "—") -> 5 | N28: =IFERROR(AVERAGEIF(N6:N25,">=1"), "—") -> 5 | O28: =IFERROR(AVERAGEIF(O6:O25,">=1"), "—") -> 3.6666667 | ... AA28: =IFERROR(AVERAGEIF(AA6:AA25,">=1"), "—") -> 3 | AB28: =IFERROR(AVERAGE(H28:AA28),"—") -> 3.9166667
B29: Desv. Estándar | H29: =IFERROR(STDEV(H6:H25),"—") -> 1 | I29: =IFERROR(STDEV(I6:I25),"—") -> 0.57735027 | J29: =IFERROR(STDEV(J6:J25),"—") -> 0.57735027 | K29: =IFERROR(STDEV(K6:K25),"—") -> 0.57735027 | L29: =IFERROR(STDEV(L6:L25),"—") -> 1.1547005 | M29: =IFERROR(STDEV(M6:M25),"—") -> 0 | N29: =IFERROR(STDEV(N6:N25),"—") -> 0 | O29: =IFERROR(STDEV(O6:O25),"—") -> 1.1547005 | ... AA29: =IFERROR(STDEV(AA6:AA25),"—") -> 2 | AB29: =IFERROR(AVERAGE(H29:AA29),"—") -> 0.80866006
B30: Mínimo | H30: =IFERROR(_xlfn.MINIFS(H6:H25,H6:H25,">=1"),"—") -> 2 | I30: =IFERROR(_xlfn.MINIFS(I6:I25,I6:I25,">=1"),"—") -> 4 | J30: =IFERROR(_xlfn.MINIFS(J6:J25,J6:J25,">=1"),"—") -> 4 | K30: =IFERROR(_xlfn.MINIFS(K6:K25,K6:K25,">=1"),"—") -> 3 | L30: =IFERROR(_xlfn.MINIFS(L6:L25,L6:L25,">=1"),"—") -> 2 | M30: =IFERROR(_xlfn.MINIFS(M6:M25,M6:M25,">=1"),"—") -> 5 | N30: =IFERROR(_xlfn.MINIFS(N6:N25,N6:N25,">=1"),"—") -> 5 | O30: =IFERROR(_xlfn.MINIFS(O6:O25,O6:O25,">=1"),"—") -> 3 | ... AA30: =IFERROR(_xlfn.MINIFS(AA6:AA25,AA6:AA25,">=1"),"—") -> 1 | AB30: =IFERROR(AVERAGE(H30:AA30),"—") -> 3.15
B31: Máximo | H31: =IFERROR(MAX(H6:H25),"—") -> 4 | I31: =IFERROR(MAX(I6:I25),"—") -> 5 | J31: =IFERROR(MAX(J6:J25),"—") -> 5 | K31: =IFERROR(MAX(K6:K25),"—") -> 4 | L31: =IFERROR(MAX(L6:L25),"—") -> 4 | M31: =IFERROR(MAX(M6:M25),"—") -> 5 | N31: =IFERROR(MAX(N6:N25),"—") -> 5 | O31: =IFERROR(MAX(O6:O25),"—") -> 5 | ... AA31: =IFERROR(MAX(AA6:AA25),"—") -> 5 | AB31: =IFERROR(AVERAGE(H31:AA31),"—") -> 4.65
B32: % Acuerdo (≥4) | H32: =IFERROR(COUNTIF(H6:H25,">=4")/COUNTIF(H6:H25,">=1"),"—") -> 0.33333333 | I32: =IFERROR(COUNTIF(I6:I25,">=4")/COUNTIF(I6:I25,">=1"),"—") -> 1 | J32: =IFERROR(COUNTIF(J6:J25,">=4")/COUNTIF(J6:J25,">=1"),"—") -> 1 | K32: =IFERROR(COUNTIF(K6:K25,">=4")/COUNTIF(K6:K25,">=1"),"—") -> 0.66666667 | L32: =IFERROR(COUNTIF(L6:L25,">=4")/COUNTIF(L6:L25,">=1"),"—") -> 0.33333333 | M32: =IFERROR(COUNTIF(M6:M25,">=4")/COUNTIF(M6:M25,">=1"),"—") -> 1 | N32: =IFERROR(COUNTIF(N6:N25,">=4")/COUNTIF(N6:N25,">=1"),"—") -> 1 | O32: =IFERROR(COUNTIF(O6:O25,">=4")/COUNTIF(O6:O25,">=1"),"—") -> 0.33333333 | ... AA32: =IFERROR(COUNTIF(AA6:AA25,">=4")/COUNTIF(AA6:AA25,">=1"),"—") -> 0.33333333 | AB32: =IFERROR(AVERAGE(H32:AA32),"—") -> 0.7

Sheet P3 3
B2: Perfil 3 — Plantilla de Ingreso de Datos
H3: Usabilidad y Personalización | M3: Recordatorios Ciclos Cortos | R3: Inventario y Reposición Ágil | W3: Interfaz y Experiencia
B4: Código | C4: Fecha | D4: Edad | E4: Género | F4: Nombres | G4: Observaciones | H4: Ítem 1 | I4: Ítem 2 | J4: Ítem 3 | K4: Ítem 4 | L4: Ítem 5 | M4: Ítem 6 | N4: Ítem 7 | O4: Ítem 8 | P4: Ítem 9 | Q4: Ítem 10 | R4: Ítem 11 | S4: Ítem 12 | T4: Ítem 13 | U4: Ítem 14 | V4: Ítem 15 | W4: Ítem 16 | X4: Ítem 17 | Y4: Ítem 18 | Z4: Ítem 19 | AA4: Ítem 20 | AB4: Promedio | AC4: Desv. Estd. | AD4: Respuestas
H5: Prefiero usar comandos de voz antes que texto en apps móviles. | I5: Me sería útil que la app me lea los recordatorios en voz alta. | J5: Usaría comandos de voz para confirmar la toma de un medicamento. | K5: Prefiero interfaces simples y con pocos objetos en pantalla | L5: Me cuesta aprender a usar aplicaciones nuevas en el celular. | M5: Las letras pequeñas me dificultan el uso de apps en el celular. | N5: Prefiero pantallas con pocos elementos y sin mucha información. | O5: El buen contraste texto/fondo me ayuda a leer mejor. | P5: Me gustaría que los botones tengan etiqueta de texto debajo del ícono. | Q5: Necesito que alguien me ayude a configurar la app inicialmente. | R5: Se me olvida con frecuencia tomar alguno de mis medicamentos. | S5: Tengo dificultades para recordar cuándo tomar cada medicamento. | T5: Me sería útil un aviso de voz y sonido en el momento de tomar el med. | U5: Necesito un informe de mis tomas para mostrar al médico o cuidador. | V5: Me ayudaría ver el horario de todos mis medicamentos del día en una pantalla. | W5: Se me ha acabado algún medicamento en casa sin darme cuenta a tiempo. | X5: Me sería útil que la app avise cuando queda poco medicamento. | Y5: Necesito recordatorios para ir a la farmacia o reclamar medicamentos. | Z5: Me gustaría que la app lleve automáticamente el conteo de pastillas. | AA5: Me sería difícil llevar un control manual de medicamentos en casa. | AB5: Auto-calculado | AC5: Auto-calculado | AD5: Auto-calculado
B6: P3-01 | C6: 45940 | D6: 25 | E6: M | F6: Alejandro Marin Pinzon | G6: Rinitis Alergica | H6: 5 | I6: 4 | J6: 5 | K6: 3 | L6: 1 | M6: 2 | N6: 2 | O6: 4 | P6: 4 | Q6: 3 | R6: 4 | S6: 4 | T6: 5 | U6: 4 | V6: 5 | W6: 4 | X6: 5 | Y6: 4 | Z6: 4 | AA6: 1 | AB6: =IFERROR(AVERAGEIF(H6:AA6,">=1"),"—") -> 3.65 | AC6: =IFERROR(STDEV(H6:AA6),"—") -> 1.2680279 | AD6: =COUNTIF(H6:AA6,">=1") -> 20
B7: P3-02 | C7: 46081 | D7: 22 | E7: F | F7: Jesica Paola Rodriguez Correa | G7: Sindrome de colon irritable | H7: 3 | I7: 3 | J7: 5 | K7: 5 | L7: 2 | M7: 3 | N7: 4 | O7: 3 | P7: 4 | Q7: 4 | R7: 3 | S7: 3 | T7: 5 | U7: 3 | V7: 5 | W7: 3 | X7: 5 | Y7: 3 | Z7: 3 | AA7: 2 | AB7: =IFERROR(AVERAGEIF(H7:AA7,">=1"),"—") -> 3.55 | AC7: =IFERROR(STDEV(H7:AA7),"—") -> 0.99868334 | AD7: =COUNTIF(H7:AA7,">=1") -> 20
B8: P3-03 | C8: 45658 | D8: 27 | E8: F | F8: Jessica Yulieth Villamil Uribe | G8: Planificacion, Patillas Hormonales | H8: 4 | I8: 3 | J8: 5 | K8: 4 | L8: 1 | M8: 3 | N8: 5 | O8: 4 | P8: 5 | Q8: 3 | R8: 5 | S8: 5 | T8: 5 | U8: 3 | V8: 5 | W8: 3 | X8: 5 | Y8: 3 | Z8: 5 | AA8: 3 | AB8: =IFERROR(AVERAGEIF(H8:AA8,">=1"),"—") -> 3.95 | AC8: =IFERROR(STDEV(H8:AA8),"—") -> 1.145931 | AD8: =COUNTIF(H8:AA8,">=1") -> 20
B9: P3-04 | C9: 45982 | D9: 23 | E9: M | F9: Luis Carlos Acevedo Gomez | G9: Esclerosis Multiple | H9: 5 | I9: 5 | J9: 5 | K9: 5 | L9: 2 | M9: 2 | N9: 4 | O9: 3 | P9: 3 | Q9: 4 | R9: 2 | S9: 2 | T9: 3 | U9: 3 | V9: 4 | W9: 2 | X9: 4 | Y9: 4 | Z9: 3 | AA9: 2 | AB9: =IFERROR(AVERAGEIF(H9:AA9,">=1"),"—") -> 3.35 | AC9: =IFERROR(STDEV(H9:AA9),"—") -> 1.1367081 | AD9: =COUNTIF(H9:AA9,">=1") -> 20
B10: P3-05 | AB10: =IFERROR(AVERAGEIF(H10:AA10,">=1"),"—") -> — | AC10: =IFERROR(STDEV(H10:AA10),"—") -> — | AD10: =COUNTIF(H10:AA10,">=1") -> 0
B11: P3-06 | AB11: =IFERROR(AVERAGEIF(H11:AA11,">=1"),"—") -> — | AC11: =IFERROR(STDEV(H11:AA11),"—") -> — | AD11: =COUNTIF(H11:AA11,">=1") -> 0
B12: P3-07 | AB12: =IFERROR(AVERAGEIF(H12:AA12,">=1"),"—") -> — | AC12: =IFERROR(STDEV(H12:AA12),"—") -> — | AD12: =COUNTIF(H12:AA12,">=1") -> 0
B13: P3-08 | AB13: =IFERROR(AVERAGEIF(H13:AA13,">=1"),"—") -> — | AC13: =IFERROR(STDEV(H13:AA13),"—") -> — | AD13: =COUNTIF(H13:AA13,">=1") -> 0
B14: P3-09 | AB14: =IFERROR(AVERAGEIF(H14:AA14,">=1"),"—") -> — | AC14: =IFERROR(STDEV(H14:AA14),"—") -> — | AD14: =COUNTIF(H14:AA14,">=1") -> 0
B15: P3-10 | AB15: =IFERROR(AVERAGEIF(H15:AA15,">=1"),"—") -> — | AC15: =IFERROR(STDEV(H15:AA15),"—") -> — | AD15: =COUNTIF(H15:AA15,">=1") -> 0
B16: P3-11 | AB16: =IFERROR(AVERAGEIF(H16:AA16,">=1"),"—") -> — | AC16: =IFERROR(STDEV(H16:AA16),"—") -> — | AD16: =COUNTIF(H16:AA16,">=1") -> 0
B17: P3-12 | AB17: =IFERROR(AVERAGEIF(H17:AA17,">=1"),"—") -> — | AC17: =IFERROR(STDEV(H17:AA17),"—") -> — | AD17: =COUNTIF(H17:AA17,">=1") -> 0
B18: P3-13 | AB18: =IFERROR(AVERAGEIF(H18:AA18,">=1"),"—") -> — | AC18: =IFERROR(STDEV(H18:AA18),"—") -> — | AD18: =COUNTIF(H18:AA18,">=1") -> 0
B19: P3-14 | AB19: =IFERROR(AVERAGEIF(H19:AA19,">=1"),"—") -> — | AC19: =IFERROR(STDEV(H19:AA19),"—") -> — | AD19: =COUNTIF(H19:AA19,">=1") -> 0
B20: P3-15 | AB20: =IFERROR(AVERAGEIF(H20:AA20,">=1"),"—") -> — | AC20: =IFERROR(STDEV(H20:AA20),"—") -> — | AD20: =COUNTIF(H20:AA20,">=1") -> 0
B21: P3-16 | AB21: =IFERROR(AVERAGEIF(H21:AA21,">=1"),"—") -> — | AC21: =IFERROR(STDEV(H21:AA21),"—") -> — | AD21: =COUNTIF(H21:AA21,">=1") -> 0
... B25: P3-20 | AB25: =IFERROR(AVERAGEIF(H25:AA25,">=1"),"—") -> — | AC25: =IFERROR(STDEV(H25:AA25),"—") -> — | AD25: =COUNTIF(H25:AA25,">=1") -> 0
B28: Media por ítem | H28: =IFERROR(AVERAGEIF(H6:H25,">=1"), "—") -> 4.25 | I28: =IFERROR(AVERAGEIF(I6:I25,">=1"), "—") -> 3.75 | J28: =IFERROR(AVERAGEIF(J6:J25,">=1"), "—") -> 5 | K28: =IFERROR(AVERAGEIF(K6:K25,">=1"), "—") -> 4.25 | L28: =IFERROR(AVERAGEIF(L6:L25,">=1"), "—") -> 1.5 | M28: =IFERROR(AVERAGEIF(M6:M25,">=1"), "—") -> 2.5 | N28: =IFERROR(AVERAGEIF(N6:N25,">=1"), "—") -> 3.75 | O28: =IFERROR(AVERAGEIF(O6:O25,">=1"), "—") -> 3.5 | ... AA28: =IFERROR(AVERAGEIF(AA6:AA25,">=1"), "—") -> 2 | AB28: =IFERROR(AVERAGE(H28:AA28),"—") -> 3.625
B29: Desv. Estándar | H29: =IFERROR(STDEV(H6:H25),"—") -> 0.95742711 | I29: =IFERROR(STDEV(I6:I25),"—") -> 0.95742711 | J29: =IFERROR(STDEV(J6:J25),"—") -> 0 | K29: =IFERROR(STDEV(K6:K25),"—") -> 0.95742711 | L29: =IFERROR(STDEV(L6:L25),"—") -> 0.57735027 | M29: =IFERROR(STDEV(M6:M25),"—") -> 0.57735027 | N29: =IFERROR(STDEV(N6:N25),"—") -> 1.2583057 | O29: =IFERROR(STDEV(O6:O25),"—") -> 0.57735027 | ... AA29: =IFERROR(STDEV(AA6:AA25),"—") -> 0.81649658 | AB29: =IFERROR(AVERAGE(H29:AA29),"—") -> 0.77531221
B30: Mínimo | H30: =IFERROR(_xlfn.MINIFS(H6:H25,H6:H25,">=1"),"—") -> 3 | I30: =IFERROR(_xlfn.MINIFS(I6:I25,I6:I25,">=1"),"—") -> 3 | J30: =IFERROR(_xlfn.MINIFS(J6:J25,J6:J25,">=1"),"—") -> 5 | K30: =IFERROR(_xlfn.MINIFS(K6:K25,K6:K25,">=1"),"—") -> 3 | L30: =IFERROR(_xlfn.MINIFS(L6:L25,L6:L25,">=1"),"—") -> 1 | M30: =IFERROR(_xlfn.MINIFS(M6:M25,M6:M25,">=1"),"—") -> 2 | N30: =IFERROR(_xlfn.MINIFS(N6:N25,N6:N25,">=1"),"—") -> 2 | O30: =IFERROR(_xlfn.MINIFS(O6:O25,O6:O25,">=1"),"—") -> 3 | ... AA30: =IFERROR(_xlfn.MINIFS(AA6:AA25,AA6:AA25,">=1"),"—") -> 1 | AB30: =IFERROR(AVERAGE(H30:AA30),"—") -> 2.75
B31: Máximo | H31: =IFERROR(MAX(H6:H25),"—") -> 5 | I31: =IFERROR(MAX(I6:I25),"—") -> 5 | J31: =IFERROR(MAX(J6:J25),"—") -> 5 | K31: =IFERROR(MAX(K6:K25),"—") -> 5 | L31: =IFERROR(MAX(L6:L25),"—") -> 2 | M31: =IFERROR(MAX(M6:M25),"—") -> 3 | N31: =IFERROR(MAX(N6:N25),"—") -> 5 | O31: =IFERROR(MAX(O6:O25),"—") -> 4 | ... AA31: =IFERROR(MAX(AA6:AA25),"—") -> 3 | AB31: =IFERROR(AVERAGE(H31:AA31),"—") -> 4.4
B32: % Acuerdo (≥4) | H32: =IFERROR(COUNTIF(H6:H25,">=4")/COUNTIF(H6:H25,">=1"),"—") -> 0.75 | I32: =IFERROR(COUNTIF(I6:I25,">=4")/COUNTIF(I6:I25,">=1"),"—") -> 0.5 | J32: =IFERROR(COUNTIF(J6:J25,">=4")/COUNTIF(J6:J25,">=1"),"—") -> 1 | K32: =IFERROR(COUNTIF(K6:K25,">=4")/COUNTIF(K6:K25,">=1"),"—") -> 0.75 | L32: =IFERROR(COUNTIF(L6:L25,">=4")/COUNTIF(L6:L25,">=1"),"—") -> 0 | M32: =IFERROR(COUNTIF(M6:M25,">=4")/COUNTIF(M6:M25,">=1"),"—") -> 0 | N32: =IFERROR(COUNTIF(N6:N25,">=4")/COUNTIF(N6:N25,">=1"),"—") -> 0.75 | O32: =IFERROR(COUNTIF(O6:O25,">=4")/COUNTIF(O6:O25,">=1"),"—") -> 0.5 | ... AA32: =IFERROR(COUNTIF(AA6:AA25,">=4")/COUNTIF(AA6:AA25,">=1"),"—") -> 0 | AB32: =IFERROR(AVERAGE(H32:AA32),"—") -> 0.5375

Sheet P4 4
B2: Perfil 4 — Plantilla de Ingreso de Datos
H3: App Como herramienta de apoyo | P3: Seguimiento y supervision del paciente | V3: Reportes y Alertas | AB3: Necesidades de accesibilidad
B4: Código | C4: Fecha | D4: Edad | E4: Género | F4: Nombres | G4: Observaciones | H4: Ítem 1 | I4: Ítem 2 | J4: Ítem 3 | K4: Ítem 4 | L4: Ítem 5 | M4: Ítem 6 | N4: Ítem 7 | O4: Ítem 8 | P4: Ítem 9 | Q4: Ítem 10 | R4: Ítem 11 | S4: Ítem 12 | T4: Ítem 13 | U4: Ítem 14 | V4: Ítem 15 | W4: Ítem 16 | X4: Ítem 17 | Y4: Ítem 18 | Z4: Ítem 19 | AA4: Ítem 20 | AB4: Ítem 21 | AC4: Ítem 22 | AD4: Ítem 23 | AE4: Ítem 24 | AF4: Ítem 25 | AG4: Ítem 26 | AH4: Promedio | AI4: Desv. Estd. | AJ4: Respuestas
H5: Considero que una aplicación móvil podría apoyar eficazmente el seguimiento del tratamiento del paciente(s) que tengo a cargo? | I5: Estaría dispuesto/a a recibir notificaciones o alertas sobre el estado de medicación del paciente? | J5: Me sería útil poder ver si el paciente confirmó o no la toma de un medicamento? | K5: Me sería útil poder ver si el paciente confirmó o no la toma de un medicamento? 2 | L5: Confiaría en los datos registrados por el paciente para tomar decisiones de cuidado? | M5: Usaría la app para tomar acciones o coordinar con otros profesionales o familiares involucrados en el cuidado? | N5: Considero que los pacientes que atiendo serían capaces de usar una aplicación medica de forma autónoma | O5: Una app de recordatorios reduciría errores en la administración de medicamentos en el hogar | P5: Necesito acceder al historial de tomas y síntomas del paciente desde mi propio dispositivo | Q5: Me sería útil recibir un resumen diario o semanal del cumplimiento del tratamiento del paciente. | R5: Es importante poder visualizar cuándo fue la última toma registrada de cada medicamento por el paciente. | S5: Necesito que la app me permita distinguir entre pacientes que siguen bien el tratamiento y los que no | T5: Me gustaría poder agregar observaciones clínicas o notas al perfil del paciente desde la app | U5: Me sería útil ver el inventario de medicamentos disponible en el hogar del paciente. | V5: Necesito recibir una alerta inmediata si el paciente no toma un medicamento crítico a tiempo. | W5: Me sería útil recibir alertas cuando el stock de medicamento del paciente esté por agotarse. | X5: Necesito que los reportes generados por la app incluyan síntomas, dosis y horarios en un solo documento. | Y5: Me gustaría poder exportar o compartir el reporte del paciente directamente al correo del médico tratante. | Z5: El formato del reporte debe ser claro, completo y legible para ser usado en una consulta médica. | AA5: Me sería útil recibir alertas si el paciente registra síntomas que requieren atención prioritaria. | AB5: Los pacientes que atiendo tienen dificultades para leer letras pequeñas en el celular. | AC5: Los pacientes que atiendo necesitan recibir instrucciones en voz alta en lugar de texto. | AD5: Los pacientes que atiendo tienen dificultades para navegar aplicaciones con muchas opciones. | AE5: Sería importante que la app funcione con comandos de voz para los pacientes que atiendo. | AF5: Los pacientes que atiendo necesitan pantallas simples con botones grandes y contraste alto. | AG5: Los pacientes que atiendo necesitan información adicional para aprender a utilizar aplicaciones móviles. | AH5: Auto-calculado | AI5: Auto-calculado | AJ5: Auto-calculado
B6: P4-01 | C6: 46113.734 | E6: M | F6: Harold nicolas duran pedraza | G6: Auxiliar de enfermeria | H6: 5 | I6: 5 | J6: 5 | K6: 5 | L6: 5 | M6: 5 | N6: 3 | O6: 5 | P6: 5 | Q6: 5 | R6: 5 | S6: 5 | T6: 5 | U6: 5 | V6: 5 | W6: 5 | X6: 5 | Y6: 5 | Z6: 5 | AA6: 5 | AB6: 3 | AC6: 3 | AD6: 5 | AE6: 3 | AF6: 3 | AG6: 5 | AH6: =IFERROR(AVERAGEIF(H6:AG6,">=1"),"—") -> 4.6153846 | AI6: =IFERROR(STDEV(H6:AG6),"—") -> 0.80383695 | AJ6: =COUNTIF(H6:AG6,">=1") -> 26
B7: P4-02 | C7: 46113.763 | E7: M | F7: Erick Serrano | G7: Enfermero | H7: 5 | I7: 5 | J7: 5 | K7: 5 | L7: 2 | M7: 5 | N7: 2 | O7: 5 | P7: 3 | Q7: 5 | R7: 5 | S7: 5 | T7: 5 | U7: 5 | V7: 5 | W7: 5 | X7: 5 | Y7: 5 | Z7: 5 | AA7: 5 | AB7: 5 | AC7: 2 | AD7: 5 | AE7: 5 | AF7: 5 | AG7: 5 | AH7: =IFERROR(AVERAGEIF(H7:AG7,">=1"),"—") -> 4.5769231 | AI7: =IFERROR(STDEV(H7:AG7),"—") -> 1.0265701 | AJ7: =COUNTIF(H7:AG7,">=1") -> 26
B8: P4-03 | C8: 46113.835 | E8: F | F8: Paula Lizeth Bermudez Ardila | G8: Enfermera | H8: 5 | I8: 5 | J8: 5 | K8: 5 | L8: 5 | M8: 5 | N8: 5 | O8: 5 | P8: 5 | Q8: 5 | R8: 5 | S8: 5 | T8: 5 | U8: 5 | V8: 5 | W8: 5 | X8: 5 | Y8: 3 | Z8: 4 | AA8: 5 | AB8: 4 | AC8: 4 | AD8: 4 | AE8: 3 | AF8: 5 | AG8: 4 | AH8: =IFERROR(AVERAGEIF(H8:AG8,">=1"),"—") -> 4.6538462 | AI8: =IFERROR(STDEV(H8:AG8),"—") -> 0.62879616 | AJ8: =COUNTIF(H8:AG8,">=1") -> 26
B9: P4-04 | C9: 46113.853 | E9: F | F9: Ángela Camila Castellanos Arenales | G9: Estudiante | H9: 5 | I9: 5 | J9: 5 | K9: 5 | L9: 3 | M9: 5 | N9: 4 | O9: 5 | P9: 5 | Q9: 5 | R9: 5 | S9: 5 | T9: 5 | U9: 5 | V9: 5 | W9: 5 | X9: 5 | Y9: 5 | Z9: 5 | AA9: 5 | AB9: 3 | AC9: 3 | AD9: 3 | AE9: 5 | AF9: 5 | AG9: 5 | AH9: =IFERROR(AVERAGEIF(H9:AG9,">=1"),"—") -> 4.6538462 | AI9: =IFERROR(STDEV(H9:AG9),"—") -> 0.74524131 | AJ9: =COUNTIF(H9:AG9,">=1") -> 26
B10: P4-05 | C10: 46114.415 | E10: F | F10: Lizeth Natalia Quiroga Pico | G10: Enfermera | H10: 5 | I10: 5 | J10: 5 | K10: 5 | L10: 3 | M10: 5 | N10: 2 | O10: 4 | P10: 5 | Q10: 5 | R10: 5 | S10: 5 | T10: 5 | U10: 5 | V10: 4 | W10: 3 | X10: 5 | Y10: 2 | Z10: 5 | AA10: 5 | AB10: 5 | AC10: 5 | AD10: 5 | AE10: 5 | AF10: 5 | AG10: 5 | AH10: =IFERROR(AVERAGEIF(H10:AG10,">=1"),"—") -> 4.5384615 | AI10: =IFERROR(STDEV(H10:AG10),"—") -> 0.94787211 | AJ10: =COUNTIF(H10:AG10,">=1") -> 26
B11: P4-06 | C11: 46116.808 | E11: F | F11: Paula Viviana samaca cañas | G11: enfermera | H11: 4 | I11: 4 | J11: 4 | K11: 4 | L11: 4 | M11: 4 | N11: 4 | O11: 4 | P11: 5 | Q11: 5 | R11: 5 | S11: 5 | T11: 3 | U11: 4 | V11: 5 | W11: 5 | X11: 4 | Y11: 5 | Z11: 5 | AA11: 5 | AB11: 3 | AC11: 3 | AD11: 5 | AE11: 4 | AF11: 4 | AG11: 4 | AH11: =IFERROR(AVERAGEIF(H11:AG11,">=1"),"—") -> 4.2692308 | AI11: =IFERROR(STDEV(H11:AG11),"—") -> 0.66679486 | AJ11: =COUNTIF(H11:AG11,">=1") -> 26
B12: P4-07 | C12: 46116.811 | E12: M | F12: Ronald | G12: Enfermero | H12: 4 | I12: 4 | J12: 4 | K12: 4 | L12: 3 | M12: 4 | N12: 3 | O12: 4 | P12: 4 | Q12: 4 | R12: 4 | S12: 4 | T12: 5 | U12: 5 | V12: 5 | W12: 5 | X12: 5 | Y12: 5 | Z12: 4 | AA12: 5 | AB12: 5 | AC12: 4 | AD12: 5 | AE12: 5 | AF12: 4 | AG12: 4 | AH12: =IFERROR(AVERAGEIF(H12:AG12,">=1"),"—") -> 4.3076923 | AI12: =IFERROR(STDEV(H12:AG12),"—") -> 0.617688 | AJ12: =COUNTIF(H12:AG12,">=1") -> 26
B13: P4-08 | C13: 46117.629 | E13: F | F13: Darly Julio | G13: Auxiliar | H13: 2 | I13: 4 | J13: 1 | K13: 2 | L13: 1 | M13: 4 | N13: 1 | O13: 2 | P13: 5 | Q13: 5 | R13: 5 | S13: 5 | T13: 5 | U13: 5 | V13: 5 | W13: 5 | X13: 5 | Y13: 5 | Z13: 5 | AA13: 5 | AB13: 5 | AC13: 5 | AD13: 5 | AE13: 5 | AF13: 5 | AG13: 3 | AH13: =IFERROR(AVERAGEIF(H13:AG13,">=1"),"—") -> 4.0384615 | AI13: =IFERROR(STDEV(H13:AG13),"—") -> 1.5094574 | AJ13: =COUNTIF(H13:AG13,">=1") -> 26
B14: P4-09 | C14: 46118.169 | E14: F | F14: Erika Melissa Villamizar Sierra | G14: Enfermera | H14: 3 | I14: 4 | J14: 4 | K14: 4 | L14: 2 | M14: 4 | N14: 3 | O14: 4 | P14: 4 | Q14: 4 | R14: 4 | S14: 4 | T14: 4 | U14: 4 | V14: 4 | W14: 4 | X14: 4 | Y14: 4 | Z14: 5 | AA14: 4 | AB14: 4 | AC14: 4 | AD14: 3 | AE14: 3 | AF14: 4 | AG14: 4 | AH14: =IFERROR(AVERAGEIF(H14:AG14,">=1"),"—") -> 3.8076923 | AI14: =IFERROR(STDEV(H14:AG14),"—") -> 0.56704362 | AJ14: =COUNTIF(H14:AG14,">=1") -> 26
B15: P4-10 | C15: 46118.705 | E15: F | F15: Yeimy Jiménez | G15: Auxiliar de enfermería | H15: 5 | I15: 5 | J15: 5 | K15: 5 | L15: 3 | M15: 5 | N15: 4 | O15: 4 | P15: 5 | Q15: 5 | R15: 5 | S15: 5 | T15: 5 | U15: 5 | V15: 5 | W15: 5 | X15: 5 | Y15: 5 | Z15: 5 | AA15: 5 | AB15: 4 | AC15: 5 | AD15: 4 | AE15: 5 | AF15: 5 | AG15: 5 | AH15: =IFERROR(AVERAGEIF(H15:AG15,">=1"),"—") -> 4.7692308 | AI15: =IFERROR(STDEV(H15:AG15),"—") -> 0.5144078 | AJ15: =COUNTIF(H15:AG15,">=1") -> 26
B16: P4-11 | C16: 46119.711 | E16: F | F16: Erika Dayana Mendez | G16: Enfermera profesional | H16: 5 | I16: 5 | J16: 5 | K16: 5 | L16: 3 | M16: 5 | N16: 5 | O16: 5 | P16: 5 | Q16: 5 | R16: 5 | S16: 5 | T16: 5 | U16: 5 | V16: 5 | W16: 5 | X16: 5 | Y16: 5 | Z16: 5 | AA16: 5 | AB16: 3 | AC16: 5 | AD16: 3 | AE16: 5 | AF16: 5 | AG16: 5 | AH16: =IFERROR(AVERAGEIF(H16:AG16,">=1"),"—") -> 4.7692308 | AI16: =IFERROR(STDEV(H16:AG16),"—") -> 0.65162519 | AJ16: =COUNTIF(H16:AG16,">=1") -> 26
B17: P4-12 | C17: 46119.767 | E17: F | F17: Nathalia Caicedo Blanco | G17: estudiante y cuidadora | H17: 4 | I17: 5 | J17: 4 | K17: 4 | L17: 4 | M17: 4 | N17: 2 | O17: 5 | P17: 5 | Q17: 3 | R17: 4 | S17: 4 | T17: 4 | U17: 4 | V17: 5 | W17: 4 | X17: 4 | Y17: 4 | Z17: 5 | AA17: 5 | AB17: 5 | AC17: 5 | AD17: 5 | AE17: 5 | AF17: 5 | AG17: 5 | AH17: =IFERROR(AVERAGEIF(H17:AG17,">=1"),"—") -> 4.3461538 | AI17: =IFERROR(STDEV(H17:AG17),"—") -> 0.74524131 | AJ17: =COUNTIF(H17:AG17,">=1") -> 26
B18: P4-13 | C18: 46133.907 | E18: F | F18: Ledi pedraza | G18: Auxiliar de enfermeria | H18: 5 | I18: 5 | J18: 5 | K18: 5 | L18: 5 | M18: 5 | N18: 4 | O18: 5 | P18: 5 | Q18: 5 | R18: 5 | S18: 5 | T18: 5 | U18: 5 | V18: 5 | W18: 5 | X18: 5 | Y18: 5 | Z18: 5 | AA18: 5 | AB18: 4 | AC18: 5 | AD18: 4 | AE18: 5 | AF18: 5 | AG18: 5 | AH18: =IFERROR(AVERAGEIF(H18:AG18,">=1"),"—") -> 4.8846154 | AI18: =IFERROR(STDEV(H18:AG18),"—") -> 0.32581259 | AJ18: =COUNTIF(H18:AG18,">=1") -> 26
B19: P4-14 | AH19: =IFERROR(AVERAGEIF(H19:AG19,">=1"),"—") -> — | AI19: =IFERROR(STDEV(H19:AG19),"—") -> — | AJ19: =COUNTIF(H19:AG19,">=1") -> 0
B20: P4-15 | AH20: =IFERROR(AVERAGEIF(H20:AG20,">=1"),"—") -> — | AI20: =IFERROR(STDEV(H20:AG20),"—") -> — | AJ20: =COUNTIF(H20:AG20,">=1") -> 0
B21: P4-16 | AH21: =IFERROR(AVERAGEIF(H21:AG21,">=1"),"—") -> — | AI21: =IFERROR(STDEV(H21:AG21),"—") -> — | AJ21: =COUNTIF(H21:AG21,">=1") -> 0
B22: P4-17 | AH22: =IFERROR(AVERAGEIF(H22:AG22,">=1"),"—") -> — | AI22: =IFERROR(STDEV(H22:AG22),"—") -> — | AJ22: =COUNTIF(H22:AG22,">=1") -> 0
B23: P4-18 | AH23: =IFERROR(AVERAGEIF(H23:AG23,">=1"),"—") -> — | AI23: =IFERROR(STDEV(H23:AG23),"—") -> — | AJ23: =COUNTIF(H23:AG23,">=1") -> 0
B24: P4-19 | AH24: =IFERROR(AVERAGEIF(H24:AG24,">=1"),"—") -> — | AI24: =IFERROR(STDEV(H24:AG24),"—") -> — | AJ24: =COUNTIF(H24:AG24,">=1") -> 0
B25: P4-20 | AH25: =IFERROR(AVERAGEIF(H25:AG25,">=1"),"—") -> — | AI25: =IFERROR(STDEV(H25:AG25),"—") -> — | AJ25: =COUNTIF(H25:AG25,">=1") -> 0
B28: Media por ítem | H28: =IFERROR(AVERAGEIF(H6:H25,">=1"), "—") -> 4.3846154 | I28: =IFERROR(AVERAGEIF(I6:I25,">=1"), "—") -> 4.6923077 | J28: =IFERROR(AVERAGEIF(J6:J25,">=1"), "—") -> 4.3846154 | K28: =IFERROR(AVERAGEIF(K6:K25,">=1"), "—") -> 4.4615385 | L28: =IFERROR(AVERAGEIF(L6:L25,">=1"), "—") -> 3.3076923 | M28: =IFERROR(AVERAGEIF(M6:M25,">=1"), "—") -> 4.6153846 | N28: =IFERROR(AVERAGEIF(N6:N25,">=1"), "—") -> 3.2307692 | O28: =IFERROR(AVERAGEIF(O6:O25,">=1"), "—") -> 4.3846154 | ... AG28: =IFERROR(AVERAGEIF(AG6:AG25,">=1"), "—") -> 4.5384615 | AH28: =IFERROR(AVERAGE(H28:AG28),"—") -> 4.4792899
B29: Desv. Estándar | H29: =IFERROR(STDEV(H6:H25),"—") -> 0.96076892 | I29: =IFERROR(STDEV(I6:I25),"—") -> 0.48038446 | J29: =IFERROR(STDEV(J6:J25),"—") -> 1.1208971 | K29: =IFERROR(STDEV(K6:K25),"—") -> 0.87705802 | L29: =IFERROR(STDEV(L6:L25),"—") -> 1.2506409 | M29: =IFERROR(STDEV(M6:M25),"—") -> 0.50636968 | N29: =IFERROR(STDEV(N6:N25),"—") -> 1.2351684 | O29: =IFERROR(STDEV(O6:O25),"—") -> 0.86971849 | ... AG29: =IFERROR(STDEV(AG6:AG25),"—") -> 0.66022529 | AH29: =IFERROR(AVERAGE(H29:AG29),"—") -> 0.71212697
B30: Mínimo | H30: =IFERROR(_xlfn.MINIFS(H6:H25,H6:H25,">=1"),"—") -> 2 | I30: =IFERROR(_xlfn.MINIFS(I6:I25,I6:I25,">=1"),"—") -> 4 | J30: =IFERROR(_xlfn.MINIFS(J6:J25,J6:J25,">=1"),"—") -> 1 | K30: =IFERROR(_xlfn.MINIFS(K6:K25,K6:K25,">=1"),"—") -> 2 | L30: =IFERROR(_xlfn.MINIFS(L6:L25,L6:L25,">=1"),"—") -> 1 | M30: =IFERROR(_xlfn.MINIFS(M6:M25,M6:M25,">=1"),"—") -> 4 | N30: =IFERROR(_xlfn.MINIFS(N6:N25,N6:N25,">=1"),"—") -> 1 | O30: =IFERROR(_xlfn.MINIFS(O6:O25,O6:O25,">=1"),"—") -> 2 | ... AG30: =IFERROR(_xlfn.MINIFS(AG6:AG25,AG6:AG25,">=1"),"—") -> 3 | AH30: =IFERROR(AVERAGE(H30:AG30),"—") -> 2.9230769
B31: Máximo | H31: =IFERROR(MAX(H6:H25),"—") -> 5 | I31: =IFERROR(MAX(I6:I25),"—") -> 5 | J31: =IFERROR(MAX(J6:J25),"—") -> 5 | K31: =IFERROR(MAX(K6:K25),"—") -> 5 | L31: =IFERROR(MAX(L6:L25),"—") -> 5 | M31: =IFERROR(MAX(M6:M25),"—") -> 5 | N31: =IFERROR(MAX(N6:N25),"—") -> 5 | O31: =IFERROR(MAX(O6:O25),"—") -> 5 | ... AG31: =IFERROR(MAX(AG6:AG25),"—") -> 5 | AH31: =IFERROR(AVERAGE(H31:AG31),"—") -> 5
B32: % Acuerdo (≥4) | H32: =IFERROR(COUNTIF(H6:H25,">=4")/COUNTIF(H6:H25,">=1"),"—") -> 0.84615385 | I32: =IFERROR(COUNTIF(I6:I25,">=4")/COUNTIF(I6:I25,">=1"),"—") -> 1 | J32: =IFERROR(COUNTIF(J6:J25,">=4")/COUNTIF(J6:J25,">=1"),"—") -> 0.92307692 | K32: =IFERROR(COUNTIF(K6:K25,">=4")/COUNTIF(K6:K25,">=1"),"—") -> 0.92307692 | L32: =IFERROR(COUNTIF(L6:L25,">=4")/COUNTIF(L6:L25,">=1"),"—") -> 0.38461538 | M32: =IFERROR(COUNTIF(M6:M25,">=4")/COUNTIF(M6:M25,">=1"),"—") -> 1 | N32: =IFERROR(COUNTIF(N6:N25,">=4")/COUNTIF(N6:N25,">=1"),"—") -> 0.46153846 | O32: =IFERROR(COUNTIF(O6:O25,">=4")/COUNTIF(O6:O25,">=1"),"—") -> 0.92307692 | ... AG32: =IFERROR(COUNTIF(AG6:AG25,">=4")/COUNTIF(AG6:AG25,">=1"),"—") -> 0.92307692 | AH32: =IFERROR(AVERAGE(H32:AG32),"—") -> 0.87573964

Sheet 📊 Análisis
B2: ANÁLISIS DESCRIPTIVO POR ÍTEM Y PERFIL
B4: # | C4: Ítem / Afirmación | D4: Media P1 (Adulto Mayor) | E4: Media P2 (Crónico Simple) | F4: Media P3 (Joven Corto) | G4: Media P4 (Cuidadores) | H4: Promedio Global | I4: Prioridad
B5: SECCIÓN A — ACCESIBILIDAD MULTIMODAL / USABILIDAD
B6: 1 | C6: Preferencia por interacción por voz | D6: =IFERROR('P1 1'!H28,"—") -> 4 | E6: =IFERROR('P2 2'!H28,"—") -> 3 | F6: =IFERROR('P3 3'!H28,"—") -> 4.25 | G6: =IFERROR('P4 4'!AE28,"—") -> 4.4615385 | H6: =IFERROR(AVERAGE(D6:G6),"—") -> 3.9278846 | I6: =IFERROR(IF(H6>=4,"🔴 Alta",IF(H6>=3,"🟡 Media","🟢 Baja")),"") -> 🟡 Media
B7: 2 | C7: Salida/retroalimentación de audio | D7: =IFERROR('P1 1'!I28,"—") -> 5 | E7: =IFERROR('P2 2'!I28,"—") -> 4.6666667 | F7: =IFERROR('P3 3'!I28,"—") -> 3.75 | G7: =IFERROR('P4 4'!AC28,"—") -> 4.0769231 | H7: =IFERROR(AVERAGE(D7:G7),"—") -> 4.3733974 | I7: =IFERROR(IF(H7>=4,"🔴 Alta",IF(H7>=3,"🟡 Media","🟢 Baja")),"") -> 🔴 Alta
B8: 3 | C8: Confirmación de toma por voz | D8: =IFERROR('P1 1'!J28,"—") -> 3.3333333 | E8: =IFERROR('P2 2'!J28,"—") -> 4.6666667 | F8: =IFERROR('P3 3'!J28,"—") -> 5 | G8: =IFERROR('P4 4'!AE28,"—") -> 4.4615385 | H8: =IFERROR(AVERAGE(D8:G8),"—") -> 4.3653846 | I8: =IFERROR(IF(H8>=4,"🔴 Alta",IF(H8>=3,"🟡 Media","🟢 Baja")),"") -> 🔴 Alta
B9: 4 | C9: Interacción táctil / botones amplios | D9: =IFERROR('P1 1'!K28,"—") -> 4 | E9: =IFERROR('P2 2'!K28,"—") -> 3.6666667 | F9: =IFERROR('P3 3'!K28,"—") -> 4.25 | G9: =IFERROR('P4 4'!AF28,"—") -> 4.6153846 | H9: =IFERROR(AVERAGE(D9:G9),"—") -> 4.1330128 | I9: =IFERROR(IF(H9>=4,"🔴 Alta",IF(H9>=3,"🟡 Media","🟢 Baja")),"") -> 🔴 Alta
B10: 5 | C10: Facilidad de aprendizaje / adopción | D10: =IFERROR('P1 1'!L28,"—") -> 5 | E10: =IFERROR('P2 2'!L28,"—") -> 2.6666667 | F10: =IFERROR('P3 3'!L28,"—") -> 1.5 | G10: =IFERROR('P4 4'!H28,"—") -> 4.3846154 | H10: =IFERROR(AVERAGE(D10:G10),"—") -> 3.3878205 | I10: =IFERROR(IF(H10>=4,"🔴 Alta",IF(H10>=3,"🟡 Media","🟢 Baja")),"") -> 🟡 Media
B11: SECCIÓN B — INTERFAZ / PLANIFICACIÓN
B12: 6 | C12: Accesibilidad visual (tamaño, fuente) | D12: =IFERROR('P1 1'!M28,"—") -> 4 | E12: =IFERROR('P2 2'!M28,"—") -> 5 | F12: =IFERROR('P3 3'!M28,"—") -> 2.5 | G12: =IFERROR('P4 4'!AB28,"—") -> 4.0769231 | H12: =IFERROR(AVERAGE(D12:G12),"—") -> 3.8942308 | I12: =IFERROR(IF(H12>=4,"🔴 Alta",IF(H12>=3,"🟡 Media","🟢 Baja")),"") -> 🟡 Media
B13: 7 | C13: Simplicidad de la interfaz | D13: =IFERROR('P1 1'!N28,"—") -> 4.3333333 | E13: =IFERROR('P2 2'!N28,"—") -> 5 | F13: =IFERROR('P3 3'!N28,"—") -> 3.75 | G13: =IFERROR('P4 4'!AD28,"—") -> 4.3076923 | H13: =IFERROR(AVERAGE(D13:G13),"—") -> 4.3477564 | I13: =IFERROR(IF(H13>=4,"🔴 Alta",IF(H13>=3,"🟡 Media","🟢 Baja")),"") -> 🔴 Alta
B14: 8 | C14: Contraste y legibilidad | D14: =IFERROR('P1 1'!O28,"—") -> 4.3333333 | E14: =IFERROR('P2 2'!O28,"—") -> 3.6666667 | F14: =IFERROR('P3 3'!O28,"—") -> 3.5 | G14: =IFERROR('P4 4'!AF28,"—") -> 4.6153846 | H14: =IFERROR(AVERAGE(D14:G14),"—") -> 4.0288462 | I14: =IFERROR(IF(H14>=4,"🔴 Alta",IF(H14>=3,"🟡 Media","🟢 Baja")),"") -> 🔴 Alta
B15: 9 | C15: Etiquetas en íconos / elementos claros | D15: =IFERROR('P1 1'!P28,"—") -> 4 | E15: =IFERROR('P2 2'!P28,"—") -> 3 | F15: =IFERROR('P3 3'!P28,"—") -> 4 | G15: =IFERROR('P4 4'!AD28,"—") -> 4.3076923 | H15: =IFERROR(AVERAGE(D15:G15),"—") -> 3.8269231 | I15: =IFERROR(IF(H15>=4,"🔴 Alta",IF(H15>=3,"🟡 Media","🟢 Baja")),"") -> 🟡 Media
B16: 10 | C16: Soporte inicial o asistencia al usuario | D16: =IFERROR('P1 1'!Q28,"—") -> 5 | E16: =IFERROR('P2 2'!Q28,"—") -> 4.3333333 | F16: =IFERROR('P3 3'!Q28,"—") -> 3.5 | G16: =IFERROR('P4 4'!AG28,"—") -> 4.5384615 | H16: =IFERROR(AVERAGE(D16:G16),"—") -> 4.3429487 | I16: =IFERROR(IF(H16>=4,"🔴 Alta",IF(H16>=3,"🟡 Media","🟢 Baja")),"") -> 🔴 Alta
B17: SECCIÓN C — INVENTARIO / RECORDATORIOS
B18: 11 | C18: Frecuencia de olvido de medicamentos | D18: =IFERROR('P1 1'!R28,"—") -> 1.6666667 | E18: =IFERROR('P2 2'!R28,"—") -> 3.3333333 | F18: =IFERROR('P3 3'!R28,"—") -> 3.5 | G18: =IFERROR('P4 4'!K28,"—") -> 4.4615385 | H18: =IFERROR(AVERAGE(D18:G18),"—") -> 3.2403846 | I18: =IFERROR(IF(H18>=4,"🔴 Alta",IF(H18>=3,"🟡 Media","🟢 Baja")),"") -> 🟡 Media
B19: 12 | C19: Dificultad en manejo de horarios | D19: =IFERROR('P1 1'!S28,"—") -> 1.6666667 | E19: =IFERROR('P2 2'!S28,"—") -> 3.3333333 | F19: =IFERROR('P3 3'!S28,"—") -> 3.5 | G19: =IFERROR('P4 4'!O28,"—") -> 4.3846154 | H19: =IFERROR(AVERAGE(D19:G19),"—") -> 3.2211538 | I19: =IFERROR(IF(H19>=4,"🔴 Alta",IF(H19>=3,"🟡 Media","🟢 Baja")),"") -> 🟡 Media
B20: 13 | C20: Recordatorio con sonido / voz | D20: =IFERROR('P1 1'!T28,"—") -> 4.6666667 | E20: =IFERROR('P2 2'!T28,"—") -> 4.6666667 | F20: =IFERROR('P3 3'!T28,"—") -> 4.5 | G20: =IFERROR('P4 4'!AC28,"—") -> 4.0769231 | H20: =IFERROR(AVERAGE(D20:G20),"—") -> 4.4775641 | I20: =IFERROR(IF(H20>=4,"🔴 Alta",IF(H20>=3,"🟡 Media","🟢 Baja")),"") -> 🔴 Alta
B21: 14 | C21: Generación de informes de adherencia | D21: =IFERROR('P1 1'!U28,"—") -> 2.6666667 | E21: =IFERROR('P2 2'!U28,"—") -> 2.3333333 | F21: =IFERROR('P3 3'!U28,"—") -> 3.25 | G21: =(IFERROR('P4 4'!L28,"—")+IFERROR('P4 4'!P28,"—")+IFERROR('P4 4'!Q28,"—")+IFERROR('P4 4'!R28,"—")+IFERROR('P4 4'!Y28,"—")+IFERROR('P4 4'!Z28,"—"))/6 -> 4.4615385 | H21: =IFERROR(AVERAGE(D21:G21),"—") -> 3.1778846 | I21: =IFERROR(IF(H21>=4,"🔴 Alta",IF(H21>=3,"🟡 Media","🟢 Baja")),"") -> 🟡 Media
B22: 15 | C22: Vista consolidada de horario diario | D22: =IFERROR('P1 1'!V28,"—") -> 2.6666667 | E22: =IFERROR('P2 2'!V28,"—") -> 4.3333333 | F22: =IFERROR('P3 3'!V28,"—") -> 4.75 | G22: =IFERROR('P4 4'!X28,"—") -> 4.7692308 | H22: =IFERROR(AVERAGE(D22:G22),"—") -> 4.1298077 | I22: =IFERROR(IF(H22>=4,"🔴 Alta",IF(H22>=3,"🟡 Media","🟢 Baja")),"") -> 🔴 Alta
B23: SECCIÓN D — EXPERIENCIA E INTEGRACIÓN
B24: 16 | C24: Desabastecimiento de medicamentos | D24: =IFERROR('P1 1'!W28,"—") -> 1.6666667 | E24: =IFERROR('P2 2'!W28,"—") -> 3.3333333 | F24: =IFERROR('P3 3'!W28,"—") -> 3 | G24: =IFERROR('P4 4'!U28,"—") -> 4.7692308 | H24: =IFERROR(AVERAGE(D24:G24),"—") -> 3.1923077 | I24: =IFERROR(IF(H24>=4,"🔴 Alta",IF(H24>=3,"🟡 Media","🟢 Baja")),"") -> 🟡 Media
B25: 17 | C25: Alerta de stock bajo | D25: =IFERROR('P1 1'!X28,"—") -> 3.6666667 | E25: =IFERROR('P2 2'!X28,"—") -> 5 | F25: =IFERROR('P3 3'!X28,"—") -> 4.75 | G25: =IFERROR('P4 4'!W28,"—") -> 4.6923077 | H25: =IFERROR(AVERAGE(D25:G25),"—") -> 4.5272436 | I25: =IFERROR(IF(H25>=4,"🔴 Alta",IF(H25>=3,"🟡 Media","🟢 Baja")),"") -> 🔴 Alta
B26: 18 | C26: Recordatorio de compra / reclamación | D26: =IFERROR('P1 1'!Y28,"—") -> 3 | E26: =IFERROR('P2 2'!Y28,"—") -> 5 | F26: =IFERROR('P3 3'!Y28,"—") -> 3.5 | G26: =IFERROR('P4 4'!Z28,"—") -> 4.8461538 | H26: =IFERROR(AVERAGE(D26:G26),"—") -> 4.0865385 | I26: =IFERROR(IF(H26>=4,"🔴 Alta",IF(H26>=3,"🟡 Media","🟢 Baja")),"") -> 🔴 Alta
B27: 19 | C27: Conteo automático de existencias | D27: =IFERROR('P1 1'!Z28,"—") -> 3.3333333 | E27: =IFERROR('P2 2'!Z28,"—") -> 4.3333333 | F27: =IFERROR('P3 3'!Z28,"—") -> 3.75 | G27: =IFERROR('P4 4'!W28,"—") -> 4.6923077 | H27: =IFERROR(AVERAGE(D27:G27),"—") -> 4.0272436 | I27: =IFERROR(IF(H27>=4,"🔴 Alta",IF(H27>=3,"🟡 Media","🟢 Baja")),"") -> 🔴 Alta
B28: 20 | C28: Dificultad en control manual | D28: =IFERROR('P1 1'!AA28,"—") -> 1.6666667 | E28: =IFERROR('P2 2'!AA28,"—") -> 3 | F28: =IFERROR('P3 3'!AA28,"—") -> 2 | G28: - | H28: =IFERROR(AVERAGE(D28:G28),"—") -> 2.2222222 | I28: =IFERROR(IF(H28>=4,"🔴 Alta",IF(H28>=3,"🟡 Media","🟢 Baja")),"") -> 🟢 Baja
B29: SECCIÓN E — SOLO CUIDADORES- Viabilidad
B30: 21 | C30: Alertas en tiempo real de seguimiento | G30: =(IFERROR('P4 4'!I28,"—")+IFERROR('P4 4'!J28,"—")+IFERROR('P4 4'!V28,"—")+IFERROR('P4 4'!AA28,"—"))/4 -> 4.7115385 | H30: =IFERROR(AVERAGE(D30:G30),"—") -> 4.7115385 | I30: =IFERROR(IF(H30>=4,"🔴 Alta",IF(H30>=3,"🟡 Media","🟢 Baja")),"") -> 🔴 Alta
B31: 22 | C31: perfilacion de pacientes según tomas | G31: =IFERROR('P4 4'!S28,"—") -> 4.7692308 | H31: =IFERROR(AVERAGE(D31:G31),"—") -> 4.7692308 | I31: =IFERROR(IF(H31>=4,"🔴 Alta",IF(H31>=3,"🟡 Media","🟢 Baja")),"") -> 🔴 Alta
B32: 23 | C32: Historial de notas por parte de cuidadores | G32: =IFERROR('P4 4'!T28,"—") -> 4.6923077 | H32: =IFERROR(AVERAGE(D32:G32),"—") -> 4.6923077 | I32: =IFERROR(IF(H32>=4,"🔴 Alta",IF(H32>=3,"🟡 Media","🟢 Baja")),"") -> 🔴 Alta
B33: 24 | C33: Viabilidad de aplicación | G33: =IFERROR('P4 4'!O28,"—") -> 4.3846154 | H33: =IFERROR(AVERAGE(D33:G33),"—") -> 4.3846154 | I33: =IFERROR(IF(H33>=4,"🔴 Alta",IF(H33>=3,"🟡 Media","🟢 Baja")),"") -> 🔴 Alta

Sheet 🔀 Comparación Perfiles
B2: COMPARACIÓN DE MEDIAS POR SECCIÓN ENTRE PERFILES
B4: Dimensión / Sección | C4: Perfil 1 Adulto Mayor | D4: Perfil 2 Crónico Simple | E4: Perfil 3 Joven Corto | F4: Perfil 4 Cuidadores | G4: Diferencia Máx–Mín
B5: Accesibilidad Multimodal | C5: =IFERROR(AVERAGE('P1 1'!H28,'P1 1'!I28,'P1 1'!J28,'P1 1'!K28,'P1 1'!L28),"—") -> 4.2666667 | D5: =IFERROR(AVERAGE('P2 2'!H28,'P2 2'!I28,'P2 2'!J28,'P2 2'!K28,'P2 2'!L28),"—") -> 3.7333333 | E5: =IFERROR(AVERAGE('P3 3'!H28,'P3 3'!I28,'P3 3'!J28,'P3 3'!K28,'P3 3'!L28),"—") -> 3.75 | F5: =IFERROR(AVERAGE('P4 4'!H28,'P4 4'!I28,'P4 4'!J28,'P4 4'!K28,'P4 4'!L28),"—") -> 4.2461538 | G5: =IFERROR(MAX(C5:F5)-MIN(C5:F5),"—") -> 0.53333333
B6: Interfaz / Usabilidad Visual | C6: =IFERROR(AVERAGE('P1 1'!M28,'P1 1'!N28,'P1 1'!O28,'P1 1'!P28,'P1 1'!Q28),"—") -> 4.3333333 | D6: =IFERROR(AVERAGE('P2 2'!M28,'P2 2'!N28,'P2 2'!O28,'P2 2'!P28,'P2 2'!Q28),"—") -> 4.2 | E6: =IFERROR(AVERAGE('P3 3'!M28,'P3 3'!N28,'P3 3'!O28,'P3 3'!P28,'P3 3'!Q28),"—") -> 3.45 | F6: =IFERROR(AVERAGE('P4 4'!M28,'P4 4'!N28,'P4 4'!O28,'P4 4'!Q28,'P4 4'!R28),"—") -> 4.3384615 | G6: =IFERROR(MAX(C6:F6)-MIN(C6:F6),"—") -> 0.88846154
B7: Planificación y Recordatorios | C7: =IFERROR(AVERAGE('P1 1'!R28,'P1 1'!S28,'P1 1'!T28,'P1 1'!U28,'P1 1'!V28),"—") -> 2.6666667 | D7: =IFERROR(AVERAGE('P2 2'!R28,'P2 2'!S28,'P2 2'!T28,'P2 2'!U28,'P2 2'!V28),"—") -> 3.6 | E7: =IFERROR(AVERAGE('P3 3'!R28,'P3 3'!S28,'P3 3'!T28,'P3 3'!U28,'P3 3'!V28),"—") -> 3.9 | F7: =IFERROR(AVERAGE('P4 4'!S28,'P4 4'!T28,'P4 4'!U28,'P4 4'!V28,'P4 4'!W28),"—") -> 4.7538462 | G7: =IFERROR(MAX(C7:F7)-MIN(C7:F7),"—") -> 2.0871795
B8: Inventario y Stock | C8: =IFERROR(AVERAGE('P1 1'!W28,'P1 1'!X28,'P1 1'!Y28,'P1 1'!Z28,'P1 1'!AA28),"—") -> 2.6666667 | D8: =IFERROR(AVERAGE('P2 2'!W28,'P2 2'!X28,'P2 2'!Y28,'P2 2'!Z28,'P2 2'!AA28),"—") -> 4.1333333 | E8: =IFERROR(AVERAGE('P3 3'!W28,'P3 3'!X28,'P3 3'!Y28,'P3 3'!Z28,'P3 3'!AA28),"—") -> 3.4 | F8: =IFERROR(AVERAGE('P4 4'!X28,'P4 4'!Y28,'P4 4'!Z28,'P4 4'!AA28,'P4 4'!AG28),"—") -> 4.7076923 | G8: =IFERROR(MAX(C8:F8)-MIN(C8:F8),"—") -> 2.0410256
B9: PROMEDIO GLOBAL | C9: =IFERROR(AVERAGE('P1 1'!H28,'P1 1'!I28,'P1 1'!J28,'P1 1'!K28,'P1 1'!L28,'P1 1'!M28,'P1 1'!N28,'P1 1'!O28,'P1 1'!P28,'P1 1'!Q28,'P1 1'!R28,'P1 1'!S28,'P1 1'!T28,'P1 1'!U28,'P1 1'!V28,'P1 1'!W28,'P1 1'!X28,'P1 1'!Y28,'P1 1'!Z28,'P1 1'!AA28),"—") -> 3.4833333 | D9: =IFERROR(AVERAGE('P2 2'!H28,'P2 2'!I28,'P2 2'!J28,'P2 2'!K28,'P2 2'!L28,'P2 2'!M28,'P2 2'!N28,'P2 2'!O28,'P2 2'!P28,'P2 2'!Q28,'P2 2'!R28,'P2 2'!S28,'P2 2'!T28,'P2 2'!U28,'P2 2'!V28,'P2 2'!W28,'P2 2'!X28,'P2 2'!Y28,'P2 2'!Z28,'P2 2'!AA28),"—") -> 3.9166667 | E9: =IFERROR(AVERAGE('P3 3'!H28,'P3 3'!I28,'P3 3'!J28,'P3 3'!K28,'P3 3'!L28,'P3 3'!M28,'P3 3'!N28,'P3 3'!O28,'P3 3'!P28,'P3 3'!Q28,'P3 3'!R28,'P3 3'!S28,'P3 3'!T28,'P3 3'!U28,'P3 3'!V28,'P3 3'!W28,'P3 3'!X28,'P3 3'!Y28,'P3 3'!Z28,'P3 3'!AA28),"—") -> 3.625 | F9: =IFERROR(AVERAGE('P4 4'!H28,'P4 4'!I28,'P4 4'!J28,'P4 4'!K28,'P4 4'!L28,'P4 4'!M28,'P4 4'!N28,'P4 4'!O28,'P4 4'!Q28,'P4 4'!R28,'P4 4'!S28,'P4 4'!T28,'P4 4'!U28,'P4 4'!V28,'P4 4'!W28,'P4 4'!X28,'P4 4'!Y28,'P4 4'!Z28,'P4 4'!AA28,'P4 4'!AG28),"—") -> 4.5115385 | G9: =IFERROR(MAX(C9:F9)-MIN(C9:F9),"—") -> 1.0282051

Sheet 📝 Preguntas Abiertas
B2: REGISTRO Y CODIFICACIÓN DE PREGUNTAS ABIERTAS
B4: Cedula Participante | C4: Perfil (1–4) | D4: Pregunta (21–25) | E4: Ítem Evaluado | F4: Respuesta del participante | G4: Categoría emergente | H4: Hallazgo clave
B5: 21737026 | C5: 1 | D5: 21
B6: 21737026 | C6: 1 | D6: 22
B7: 21737026 | C7: 1 | D7: 23
B8: 21737026 | C8: 1 | D8: 24
B9: 21737026 | C9: 1 | D9: 25

Sheet 🏆 Requisitos Prioritarios
B2: RANKING DE REQUISITOS PRIORIZADOS POR EVIDENCIA DE USUARIOS
B3: Los promedios se calculan automáticamente desde la hoja 'Análisis'. Ordenar manualmente de mayor a menor por 'Media Global' para obtener el ranking.
B4: Pos. | C4: Requisito / Funcionalidad | D4: Media Global | E4: Prioridad MVP | F4: Perfil que más lo demanda | G4: Módulo de la app
B5: 1 | C5: Preferencia por interacción por voz | D5: =IFERROR('📊 Análisis'!H6,"—") -> 3.9278846 | E5: =IFERROR(IF(D5>=4,"🔴 Alta",IF(D5>=3,"🟡 Media","🟢 Baja")),"") -> 🟡 Media
B6: 2 | C6: Salida/retroalimentación de audio | D6: =IFERROR('📊 Análisis'!H7,"—") -> 4.3733974 | E6: =IFERROR(IF(D6>=4,"🔴 Alta",IF(D6>=3,"🟡 Media","🟢 Baja")),"") -> 🔴 Alta
B7: 3 | C7: Confirmación de toma por voz | D7: =IFERROR('📊 Análisis'!H8,"—") -> 4.3653846 | E7: =IFERROR(IF(D7>=4,"🔴 Alta",IF(D7>=3,"🟡 Media","🟢 Baja")),"") -> 🔴 Alta
B8: 4 | C8: Interacción táctil / botones amplios | D8: =IFERROR('📊 Análisis'!H9,"—") -> 4.1330128 | E8: =IFERROR(IF(D8>=4,"🔴 Alta",IF(D8>=3,"🟡 Media","🟢 Baja")),"") -> 🔴 Alta
B9: 5 | C9: Facilidad de aprendizaje / adopción | D9: =IFERROR('📊 Análisis'!H10,"—") -> 3.3878205 | E9: =IFERROR(IF(D9>=4,"🔴 Alta",IF(D9>=3,"🟡 Media","🟢 Baja")),"") -> 🟡 Media
B10: 6 | C10: Accesibilidad visual (tamaño, contraste) | D10: =IFERROR('📊 Análisis'!H12,"—") -> 3.8942308 | E10: =IFERROR(IF(D10>=4,"🔴 Alta",IF(D10>=3,"🟡 Media","🟢 Baja")),"") -> 🟡 Media
B11: 7 | C11: Simplicidad de la interfaz | D11: =IFERROR('📊 Análisis'!H13,"—") -> 4.3477564 | E11: =IFERROR(IF(D11>=4,"🔴 Alta",IF(D11>=3,"🟡 Media","🟢 Baja")),"") -> 🔴 Alta
B12: 8 | C12: Contraste y legibilidad | D12: =IFERROR('📊 Análisis'!H14,"—") -> 4.0288462 | E12: =IFERROR(IF(D12>=4,"🔴 Alta",IF(D12>=3,"🟡 Media","🟢 Baja")),"") -> 🔴 Alta
B13: 9 | C13: Etiquetas en íconos / elementos claros | D13: =IFERROR('📊 Análisis'!H15,"—") -> 3.8269231 | E13: =IFERROR(IF(D13>=4,"🔴 Alta",IF(D13>=3,"🟡 Media","🟢 Baja")),"") -> 🟡 Media
B14: 10 | C14: Soporte inicial o asistencia al usuario | D14: =IFERROR('📊 Análisis'!H16,"—") -> 4.3429487 | E14: =IFERROR(IF(D14>=4,"🔴 Alta",IF(D14>=3,"🟡 Media","🟢 Baja")),"") -> 🔴 Alta
B15: 11 | C15: Frecuencia de olvido de medicamentos | D15: =IFERROR('📊 Análisis'!H18,"—") -> 3.2403846 | E15: =IFERROR(IF(D15>=4,"🔴 Alta",IF(D15>=3,"🟡 Media","🟢 Baja")),"") -> 🟡 Media
B16: 12 | C16: Dificultad en manejo de horarios | D16: =IFERROR('📊 Análisis'!H19,"—") -> 3.2211538 | E16: =IFERROR(IF(D16>=4,"🔴 Alta",IF(D16>=3,"🟡 Media","🟢 Baja")),"") -> 🟡 Media
B17: 13 | C17: Recordatorio con sonido / voz | D17: =IFERROR('📊 Análisis'!H20,"—") -> 4.4775641 | E17: =IFERROR(IF(D17>=4,"🔴 Alta",IF(D17>=3,"🟡 Media","🟢 Baja")),"") -> 🔴 Alta
B18: 14 | C18: Generación de informes de adherencia | D18: =IFERROR('📊 Análisis'!H21,"—") -> 3.1778846 | E18: =IFERROR(IF(D18>=4,"🔴 Alta",IF(D18>=3,"🟡 Media","🟢 Baja")),"") -> 🟡 Media
B19: 15 | C19: Vista consolidada de horario diario | D19: =IFERROR('📊 Análisis'!H22,"—") -> 4.1298077 | E19: =IFERROR(IF(D19>=4,"🔴 Alta",IF(D19>=3,"🟡 Media","🟢 Baja")),"") -> 🔴 Alta
B20: 16 | C20: Desabastecimiento de medicamentos | D20: =IFERROR('📊 Análisis'!H24,"—") -> 3.1923077 | E20: =IFERROR(IF(D20>=4,"🔴 Alta",IF(D20>=3,"🟡 Media","🟢 Baja")),"") -> 🟡 Media
B21: 17 | C21: Alerta de stock bajo | D21: =IFERROR('📊 Análisis'!H25,"—") -> 4.5272436 | E21: =IFERROR(IF(D21>=4,"🔴 Alta",IF(D21>=3,"🟡 Media","🟢 Baja")),"") -> 🔴 Alta
B22: 18 | C22: Recordatorio de compra / reclamación | D22: =IFERROR('📊 Análisis'!H26,"—") -> 4.0865385 | E22: =IFERROR(IF(D22>=4,"🔴 Alta",IF(D22>=3,"🟡 Media","🟢 Baja")),"") -> 🔴 Alta
B23: 19 | C23: Conteo automático de existencias | D23: =IFERROR('📊 Análisis'!H27,"—") -> 4.0272436 | E23: =IFERROR(IF(D23>=4,"🔴 Alta",IF(D23>=3,"🟡 Media","🟢 Baja")),"") -> 🔴 Alta
B24: 20 | C24: Dificultad en control manual | D24: =IFERROR('📊 Análisis'!H28,"—") -> 2.2222222 | E24: =IFERROR(IF(D24>=4,"🔴 Alta",IF(D24>=3,"🟡 Media","🟢 Baja")),"") -> 🟢 Baja

Sheet Benchmarkin App
B2: Perfil 1 | H2: Perfil 2 | N2: Perfil 3
B5: Dimensión 1: Accesibilidad Multimodal — Énfasis en voz para adultos mayores | H5: Dimensión 1: Accesibilidad Multimodal — Énfasis en voz para adultos | N5: Dimensión 1: Accesibilidad Multimodal — Énfasis en voz para jovenes
B7: Criterio | C7: Medisafe | D7: MyTherapy | E7: Pill Reminder-Sergio Licea App | H7: Criterio | I7: Medisafe | J7: MyTherapy | K7: Pill Reminder-Sergio Licea App | N7: Criterio | O7: Medisafe | P7: MyTherapy | Q7: Pill Reminder-Sergio Licea App
B8: Entrada por reconocimiento de voz (STT) | C8: 0 | D8: 0 | E8: 0 | H8: Entrada por reconocimiento de voz (STT) | I8: 0 | J8: 0 | K8: 0 | N8: Entrada por reconocimiento de voz (STT) | O8: 0 | P8: 0 | Q8: 0
B9: Respuesta auditiva / síntesis de voz (TTS) | C9: 2 | D9: 1 | E9: 0 | H9: Respuesta auditiva / síntesis de voz (TTS) | I9: 2 | J9: 1 | K9: 0 | N9: Respuesta auditiva / síntesis de voz (TTS) | O9: 2 | P9: 1 | Q9: 0
B10: Confirmación vocal de toma de medicamento | C10: 0 | D10: 0 | E10: 0 | H10: Confirmación vocal de toma de medicamento | I10: 0 | J10: 0 | K10: 0 | N10: Confirmación vocal de toma de medicamento | O10: 0 | P10: 0 | Q10: 0
B11: Interacción táctil con botones amplios | C11: 4 | D11: 4 | E11: 3 | H11: Interacción táctil con botones amplios | I11: 4 | J11: 4 | K11: 3 | N11: Interacción táctil con botones amplios | O11: 4 | P11: 4 | Q11: 3
B12: Lector de pantalla / narración automática | C12: 3 | D12: 3 | E12: 2 | H12: Lector de pantalla / narración automática | I12: 3 | J12: 3 | K12: 2 | N12: Lector de pantalla / narración automática | O12: 3 | P12: 3 | Q12: 2
B13: Alternativa de texto cuando la voz falla | C13: 5 | D13: 5 | E13: 4 | H13: Alternativa de texto cuando la voz falla | I13: 5 | J13: 5 | K13: 4 | N13: Alternativa de texto cuando la voz falla | O13: 5 | P13: 5 | Q13: 4
B14: Soporte sin necesidad de escritura con teclado | C14: 4 | D14: 4 | E14: 3 | H14: Soporte sin necesidad de escritura con teclado | I14: 4 | J14: 4 | K14: 3 | N14: Soporte sin necesidad de escritura con teclado | O14: 4 | P14: 4 | Q14: 3
B15: Totales max 35 | C15: =SUM(C8:C14) -> 18 | D15: =SUM(D8:D14) -> 17 | E15: =SUM(E8:E14) -> 12 | H15: Totales max 35 | I15: =SUM(I8:I14) -> 18 | J15: =SUM(J8:J14) -> 17 | K15: =SUM(K8:K14) -> 12 | N15: Totales max 35 | O15: =SUM(O8:O14) -> 18 | P15: =SUM(P8:P14) -> 17 | Q15: =SUM(Q8:Q14) -> 12
B17: Dimensión 2: Interfaz para Adultos Mayores | H17: Dimensión 2: Interfaz para Adultos | N17: Dimensión 2: Interfaz moderna
B19: Criterio | C19: Medisafe | D19: MyTherapy | E19: Pill Reminder-Sergio Licea App | H19: Criterio | I19: Medisafe | J19: MyTherapy | K19: Pill Reminder-Sergio Licea App | N19: Criterio | O19: Medisafe | P19: MyTherapy | Q19: Pill Reminder-Sergio Licea App
B20: Tamaño de fuente ≥ 16pt en toda la interfaz | C20: 3 | D20: 3 | E20: 2 | H20: Tamaño de fuente ≥ 16pt en toda la interfaz | I20: 3 | J20: 3 | K20: 2 | N20: Tamaño de fuente entendible en toda la interfaz | O20: 3 | P20: 3 | Q20: 2
B21: Alto contraste texto / fondo | C21: 4 | D21: 4 | E21: 3 | H21: Alto contraste texto / fondo / modo nocturno | I21: 4 | J21: 4 | K21: 3 | N21: Alto contraste texto / fondo / modo nocturno | O21: 4 | P21: 4 | Q21: 3
B22: Botones grandes y bien espaciados | C22: 4 | D22: 4 | E22: 3 | H22: Botones grandes y bien espaciados | I22: 4 | J22: 4 | K22: 3 | N22: Botones grandes y bien espaciados | O22: 4 | P22: 4 | Q22: 3
B23: Flujos simples (máx. 3 pasos por tarea) | C23: 3 | D23: 3 | E23: 4 | H23: Flujos simples (máx. 3 pasos por tarea) | I23: 3 | J23: 3 | K23: 4 | N23: Flujos simples (máx. 3 pasos por tarea) | O23: 3 | P23: 3 | Q23: 4
B24: Íconos con etiqueta de texto descriptiva | C24: 4 | D24: 4 | E24: 3 | H24: Íconos con etiqueta de texto descriptiva | I24: 4 | J24: 4 | K24: 3 | N24: Íconos con etiqueta de texto descriptiva | O24: 4 | P24: 4 | Q24: 3
B25: Modo de accesibilidad o ajuste de tamaño | C25: 4 | D25: 4 | E25: 2 | H25: Modo de accesibilidad o ajuste de tamaño | I25: 4 | J25: 4 | K25: 2 | N25: Modo de accesibilidad o ajuste de tamaño | O25: 4 | P25: 4 | Q25: 2
